<?xml version="1.0"?>
<robot name="Manipulobot" xmlns:xacro="http://www.ros.org/wiki/xacro">

  <material name="Red">
    <color rgba="0.6 0.0 0.0 1.0"/>
  </material>
  <material name="LightGrey">
    <color rgba="0.5 0.5 0.5 1.0"/>
  </material>
  <material name="orange">
    <color rgba="1.0 0.423529411765 0.0392156862745 1.0"/>
  </material>
  <material name="Black">
    <color rgba="0 0 0 1"/>
  </material>
  <material name="Blue">
    <color rgba="0 0 0.5 1"/>
  </material>
  <material name="Green">
    <color rgba="0 0.5 0 1"/>
  </material>
  
  <!-- ROS base_platform to World Coordinates transform -->
  <link name="world"/>
  <joint name="world_joint" type="fixed">
    <origin rpy="0.0 0.0 0.0" xyz="0.0 0.0 0.0"/>
    <parent link="world"/>
    <child link="base_link"/>
  </joint>
  <!-- link list -->

  <link name="base_link">
    <visual>
      <origin rpy="0 0 0" xyz="0.0 0.0 0.073145"/>
      <geometry>
        <box size="0.26670 0.17760 0.00635"/>
      </geometry>
      <material name="Black"/>
    </visual>
    <collision>
      <origin rpy="0 0 0" xyz="0.0 0.0 0.073145"/>
      <geometry>
        <box size="0.26670 0.17760 0.00635"/>
      </geometry>
    </collision>
  </link>

  <joint name="platform_joints" type="fixed">
    <origin rpy="0 0 0" xyz="0 0 0"/>
    <parent link="base_link"/>
    <child link="base_platform_2"/>
  </joint>

  <link name="base_platform_2">
    <visual>
      <origin rpy="0 0 0" xyz="0.0 0.0 0.114495"/>
      <geometry>
        <box size="0.26670 0.17760 0.00635"/>
      </geometry>
      <material name="Black"/>
    </visual>
    <collision>
      <origin rpy="0 0 0" xyz="0.0 0.0 0.114495"/>
      <geometry>
        <box size="0.26670 0.17760 0.00635"/>
      </geometry>
    </collision>
  </link>

  <link name="wheel_left_top">
    <visual>
      <origin rpy="1.57 0 0" xyz="0.0 0.0 0.00"/>
      <geometry>
        <cylinder length="0.039" radius="0.030"/>
      </geometry>
        <material name="Red"/>
    </visual>
    <collision>
      <origin rpy="1.57 0 0" xyz="0.0 0.0 0.00"/>
      <geometry>
        <cylinder length="0.039" radius="0.030"/>
      </geometry>
    </collision>
  </link>

  <link name="wheel_left_bottom">
    <visual>
      <origin rpy="1.57 0 0" xyz="0.00 0.0 0.0"/>
      <geometry>
        <cylinder length="0.039" radius="0.030"/>
      </geometry>
        <material name="Red"/>
    </visual>
    <collision>
      <origin rpy="1.57 0 0" xyz="0.0 0.0 0.00"/>
      <geometry>
        <cylinder length="0.039" radius="0.030"/>
      </geometry>
    </collision>
  </link>

  <link name="wheel_right_top">
    <visual>
      <origin rpy="1.57 0 0" xyz="0.0 0.0 0.00"/>
      <geometry>
        <cylinder length="0.039" radius="0.030"/>
      </geometry>
        <material name="Red"/>
    </visual>
    <collision>
      <origin rpy="1.57 0 0" xyz="0.0 0.0 0.00"/>
      <geometry>
        <cylinder length="0.039" radius="0.030"/>
      </geometry>
    </collision>
  </link>

  <link name="wheel_right_bottom">
    <visual>
      <origin rpy="1.57 0 0" xyz="0.00 0.0 0.00"/>
      <geometry>
        <cylinder length="0.039" radius="0.030"/>
      </geometry>
        <material name="Red"/>
    </visual>
    <collision>
      <origin rpy="1.57 0 0" xyz="0.0 0.0 0.00"/>
      <geometry>
        <cylinder length="0.039" radius="0.030"/>
      </geometry>
    </collision>
  </link>

  <joint name="platform_1_wheel_left_top_joint" type="continuous">
    <origin rpy="0 0 0" xyz="0.095 0.1290 0.04"/>
    <parent link="base_link"/>
    <child link="wheel_left_top"/>
    <axis xyz="0 1 0"/>
  </joint>

  <joint name="platform_1_wheel_left_bottom_joint" type="continuous">
    <origin rpy="0 0 0" xyz="-0.095 0.1290 0.04"/>
    <parent link="base_link"/>
    <child link="wheel_left_bottom"/>
    <axis xyz="0 1 0"/>
  </joint>

  <joint name="platform_1_wheel_right_top_joint" type="continuous">
    <origin rpy="0 0 0" xyz="0.095 -0.1290 0.04"/>
    <parent link="base_link"/>
    <child link="wheel_right_top"/>
    <axis xyz="0 1 0"/>
  </joint>

  <joint name="platform_1_wheel_right_bottom_joint" type="continuous">
    <origin rpy="0 0 0" xyz="-0.095 -0.1290 0.04"/>
    <parent link="base_link"/>
    <child link="wheel_right_bottom"/>
    <axis xyz="0 1 0"/>
  </joint>

  <link name="wheel_left_top_bracket">
    <visual>
      <origin rpy="0 0 0" xyz="0.0 0.0 0.00"/>
      <geometry>
        <box size="0.04 0.01 0.04"/>
      </geometry>
        <material name="Blue"/>
    </visual>
    <collision>
      <origin rpy="0.0 0 0" xyz="0.0 0.0 0.00"/>
      <geometry>
        <box size="0.04 0.01 0.04"/>
      </geometry>
    </collision>
  </link>

  <link name="wheel_left_bottom_bracket">
    <visual>
      <origin rpy="0 0 0" xyz="0.0 0.0 0.0"/>
      <geometry>
        <box size="0.04 0.01 0.04"/>
      </geometry>
        <material name="Blue"/>
    </visual>
    <collision>
      <origin rpy="0 0 0" xyz="0.0 0.0 0.00"/>
      <geometry>
        <box size="0.04 0.01 0.04"/>
      </geometry>
    </collision>
  </link>

  <link name="wheel_right_top_bracket">
    <visual>
      <origin rpy="0 0 0" xyz="0.0 0.0 0.00"/>
      <geometry>
        <box size="0.04 0.01 0.04"/>
      </geometry>
        <material name="Blue"/>
    </visual>
    <collision>
      <origin rpy="0 0 0" xyz="0.0 0.0 0.00"/>
      <geometry>
        <box size="0.04 0.01 0.04"/>
      </geometry>
    </collision>
  </link>

  <link name="wheel_right_bottom_bracket">
    <visual>
      <origin rpy="0 0 0" xyz="0.0 0.0 0.00"/>
      <geometry>
        <box size="0.04 0.01 0.04"/>
      </geometry>
        <material name="Blue"/>
    </visual>
    <collision>
      <origin rpy="0 0 0" xyz="0.0 0.0 0.00"/>
      <geometry>
        <box size="0.04 0.01 0.04"/>
      </geometry>
    </collision>
  </link>

  <joint name="platform_1_wheel_left_top_bracket_fixed" type="fixed">
    <origin rpy="0 0 0" xyz="0.095 0.0840 0.05"/>
    <parent link="base_link"/>
    <child link="wheel_left_top_bracket"/>
  </joint>

  <joint name="platform_1_wheel_left_bottom_bracket_fixed" type="fixed">
    <origin rpy="0 0 0" xyz="-0.095 0.0840 0.05"/>
    <parent link="base_link"/>
    <child link="wheel_left_bottom_bracket"/>
  </joint>

  <joint name="platform_1_wheel_right_top_bracket_fixed" type="fixed">
    <origin rpy="0 0 0" xyz="0.095 -0.0840 0.05"/>
    <parent link="base_link"/>
    <child link="wheel_right_top_bracket"/>
  </joint>

  <joint name="platform_1_wheel_right_bottom_bracket_fixed" type="fixed">
    <origin rpy="0 0 0" xyz="-0.095 -0.0840 0.05"/>
    <parent link="base_link"/>
    <child link="wheel_right_bottom_bracket"/>
  </joint>

  <link name="wheel_left_top_shaft">
    <visual>
      <origin rpy="1.57079633 0 0" xyz="0.0 0.0 0.00"/>
      <geometry>
        <cylinder length="0.0205" radius="0.005"/>
      </geometry>
        <material name="Green"/>
    </visual>
    <collision>
      <origin rpy="1.57079633 0 0" xyz="0.0 0.0 0.00"/>
      <geometry>
        <cylinder length="0.0205" radius="0.005"/>
      </geometry>
    </collision>
  </link>

  <link name="wheel_left_bottom_shaft">
    <visual>
      <origin rpy="1.57079633 0 0" xyz="0.0 0.0 0.0"/>
      <geometry>
        <cylinder length="0.0205" radius="0.005"/>
      </geometry>
        <material name="Green"/>
    </visual>
    <collision>
      <origin rpy="1.57079633 0 0" xyz="0.0 0.0 0.00"/>
      <geometry>
        <cylinder length="0.0205" radius="0.005"/>
      </geometry>
    </collision>
  </link>

  <link name="wheel_right_top_shaft">
    <visual>
      <origin rpy="1.57079633 0 0" xyz="0.0 0.0 0.00"/>
      <geometry>
        <cylinder length="0.0205" radius="0.005"/>
      </geometry>
        <material name="Green"/>
    </visual>
    <collision>
      <origin rpy="1.57079633 0 0" xyz="0.0 0.0 0.00"/>
      <geometry>
        <cylinder length="0.0205" radius="0.005"/>
      </geometry>
    </collision>
  </link>

  <link name="wheel_right_bottom_shaft">
    <visual>
      <origin rpy="1.57079633 0 0" xyz="0.0 0.0 0.00"/>
      <geometry>
        <cylinder length="0.0205" radius="0.005"/>
      </geometry>
        <material name="Green"/>
    </visual>
    <collision>
      <origin rpy="1.57079633 0 0" xyz="0.0 0.0 0.00"/>
      <geometry>
        <cylinder length="0.0205" radius="0.005"/>
      </geometry>
    </collision>
  </link>

  <joint name="wheel_left_top_bracket_shaft_fixed" type="fixed">
    <origin rpy="0 0 0" xyz="0.0 0.015 -0.0150"/>
    <parent link="wheel_left_top_bracket"/>
    <child link="wheel_left_top_shaft"/>
  </joint>

  <joint name="wheel_left_bottom_bracket_shaft_fixed" type="fixed">
    <origin rpy="0 0 0" xyz="0.0 0.015 -0.0150"/>
    <parent link="wheel_left_bottom_bracket"/>
    <child link="wheel_left_bottom_shaft"/>
  </joint>

  <joint name="wheel_right_top_bracket_shaft_fixed" type="fixed">
    <origin rpy="0 0 0" xyz="0.0 -0.015 -0.0150"/>
    <parent link="wheel_right_top_bracket"/>
    <child link="wheel_right_top_shaft"/>
  </joint>

  <joint name="wheel_right_bottom_bracket_shaft_fixed" type="fixed">
    <origin rpy="0 0 0" xyz="0.0 -0.015 -0.0150"/>
    <parent link="wheel_right_bottom_bracket"/>
    <child link="wheel_right_bottom_shaft"/>
  </joint>

</robot>
